2022-11-23 16:12:26,265 INFO    MainThread:29876 [wandb_setup.py:_flush():68] Configure stats pid to 29876
2022-11-23 16:12:26,265 INFO    MainThread:29876 [wandb_setup.py:_flush():68] Loading settings from C:\Users\adams\.config\wandb\settings
2022-11-23 16:12:26,265 INFO    MainThread:29876 [wandb_setup.py:_flush():68] Loading settings from C:\Users\adams\OneDrive\Documents\GitHub\Mavi\wandb\settings
2022-11-23 16:12:26,265 INFO    MainThread:29876 [wandb_setup.py:_flush():68] Loading settings from environment variables: {'_require_service': 'True'}
2022-11-23 16:12:26,265 INFO    MainThread:29876 [wandb_setup.py:_flush():68] Inferring run settings from compute environment: {'program_relpath': '..\\..\\..\\..\\AppData\\Local\\Programs\\Python\\Python39\\lib\\site-packages\\ray\\_private\\workers\\default_worker.py', 'program': 'C:\\Users\\adams\\AppData\\Local\\Programs\\Python\\Python39\\lib\\site-packages\\ray\\_private\\workers\\default_worker.py'}
2022-11-23 16:12:26,265 INFO    MainThread:29876 [wandb_init.py:_log_setup():476] Logging user logs to C:\Users\adams\OneDrive\Documents\GitHub\Mavi\wandb\run-20221123_161226-1f4htvl0\logs\debug.log
2022-11-23 16:12:26,265 INFO    MainThread:29876 [wandb_init.py:_log_setup():477] Logging internal logs to C:\Users\adams\OneDrive\Documents\GitHub\Mavi\wandb\run-20221123_161226-1f4htvl0\logs\debug-internal.log
2022-11-23 16:12:26,265 INFO    MainThread:29876 [wandb_init.py:init():516] calling init triggers
2022-11-23 16:12:26,265 INFO    MainThread:29876 [wandb_init.py:init():519] wandb.init called with sweep_config: {}
config: {}
2022-11-23 16:12:26,265 INFO    MainThread:29876 [wandb_init.py:init():569] starting backend
2022-11-23 16:12:26,265 INFO    MainThread:29876 [wandb_init.py:init():573] setting up manager
2022-11-23 16:12:26,265 INFO    MainThread:29876 [backend.py:_multiprocessing_setup():102] multiprocessing start_methods=spawn, using: spawn
2022-11-23 16:12:26,265 INFO    MainThread:29876 [wandb_init.py:init():580] backend started and connected
2022-11-23 16:12:26,282 INFO    MainThread:29876 [wandb_init.py:init():658] updated telemetry
2022-11-23 16:12:26,306 INFO    MainThread:29876 [wandb_init.py:init():693] communicating run to backend with 60 second timeout
2022-11-23 16:12:34,747 ERROR   Thread-8  :29876 [retry.py:__call__():154] Retry attempt failed:
Traceback (most recent call last):
  File "C:\Users\adams\AppData\Local\Programs\Python\Python39\lib\site-packages\urllib3\connection.py", line 174, in _new_conn
    conn = connection.create_connection(
  File "C:\Users\adams\AppData\Local\Programs\Python\Python39\lib\site-packages\urllib3\util\connection.py", line 72, in create_connection
    for res in socket.getaddrinfo(host, port, family, socket.SOCK_STREAM):
  File "C:\Users\adams\AppData\Local\Programs\Python\Python39\lib\socket.py", line 953, in getaddrinfo
    for res in _socket.getaddrinfo(host, port, family, type, proto, flags):
socket.gaierror: [Errno 11002] getaddrinfo failed

During handling of the above exception, another exception occurred:

Traceback (most recent call last):
  File "C:\Users\adams\AppData\Local\Programs\Python\Python39\lib\site-packages\urllib3\connectionpool.py", line 703, in urlopen
    httplib_response = self._make_request(
  File "C:\Users\adams\AppData\Local\Programs\Python\Python39\lib\site-packages\urllib3\connectionpool.py", line 386, in _make_request
    self._validate_conn(conn)
  File "C:\Users\adams\AppData\Local\Programs\Python\Python39\lib\site-packages\urllib3\connectionpool.py", line 1042, in _validate_conn
    conn.connect()
  File "C:\Users\adams\AppData\Local\Programs\Python\Python39\lib\site-packages\urllib3\connection.py", line 358, in connect
    self.sock = conn = self._new_conn()
  File "C:\Users\adams\AppData\Local\Programs\Python\Python39\lib\site-packages\urllib3\connection.py", line 186, in _new_conn
    raise NewConnectionError(
urllib3.exceptions.NewConnectionError: <urllib3.connection.HTTPSConnection object at 0x0000023F5EF71490>: Failed to establish a new connection: [Errno 11002] getaddrinfo failed

During handling of the above exception, another exception occurred:

Traceback (most recent call last):
  File "C:\Users\adams\AppData\Local\Programs\Python\Python39\lib\site-packages\requests\adapters.py", line 489, in send
    resp = conn.urlopen(
  File "C:\Users\adams\AppData\Local\Programs\Python\Python39\lib\site-packages\urllib3\connectionpool.py", line 787, in urlopen
    retries = retries.increment(
  File "C:\Users\adams\AppData\Local\Programs\Python\Python39\lib\site-packages\urllib3\util\retry.py", line 592, in increment
    raise MaxRetryError(_pool, url, error or ResponseError(cause))
urllib3.exceptions.MaxRetryError: HTTPSConnectionPool(host='api.wandb.ai', port=443): Max retries exceeded with url: /graphql (Caused by NewConnectionError('<urllib3.connection.HTTPSConnection object at 0x0000023F5EF71490>: Failed to establish a new connection: [Errno 11002] getaddrinfo failed'))

During handling of the above exception, another exception occurred:

Traceback (most recent call last):
  File "C:\Users\adams\AppData\Local\Programs\Python\Python39\lib\site-packages\wandb\sdk\lib\retry.py", line 113, in __call__
    result = self._call_fn(*args, **kwargs)
  File "C:\Users\adams\AppData\Local\Programs\Python\Python39\lib\site-packages\wandb\sdk\internal\internal_api.py", line 213, in execute
    return self.client.execute(*args, **kwargs)  # type: ignore
  File "C:\Users\adams\AppData\Local\Programs\Python\Python39\lib\site-packages\wandb\vendor\gql-0.2.0\wandb_gql\client.py", line 52, in execute
    result = self._get_result(document, *args, **kwargs)
  File "C:\Users\adams\AppData\Local\Programs\Python\Python39\lib\site-packages\wandb\vendor\gql-0.2.0\wandb_gql\client.py", line 60, in _get_result
    return self.transport.execute(document, *args, **kwargs)
  File "C:\Users\adams\AppData\Local\Programs\Python\Python39\lib\site-packages\wandb\vendor\gql-0.2.0\wandb_gql\transport\requests.py", line 38, in execute
    request = requests.post(self.url, **post_args)
  File "C:\Users\adams\AppData\Local\Programs\Python\Python39\lib\site-packages\requests\api.py", line 115, in post
    return request("post", url, data=data, json=json, **kwargs)
  File "C:\Users\adams\AppData\Local\Programs\Python\Python39\lib\site-packages\requests\api.py", line 59, in request
    return session.request(method=method, url=url, **kwargs)
  File "C:\Users\adams\AppData\Local\Programs\Python\Python39\lib\site-packages\requests\sessions.py", line 587, in request
    resp = self.send(prep, **send_kwargs)
  File "C:\Users\adams\AppData\Local\Programs\Python\Python39\lib\site-packages\requests\sessions.py", line 701, in send
    r = adapter.send(request, **kwargs)
  File "C:\Users\adams\AppData\Local\Programs\Python\Python39\lib\site-packages\requests\adapters.py", line 565, in send
    raise ConnectionError(e, request=request)
requests.exceptions.ConnectionError: HTTPSConnectionPool(host='api.wandb.ai', port=443): Max retries exceeded with url: /graphql (Caused by NewConnectionError('<urllib3.connection.HTTPSConnection object at 0x0000023F5EF71490>: Failed to establish a new connection: [Errno 11002] getaddrinfo failed'))
