2022-11-23 16:01:54,596 INFO    StreamThr :3052 [internal.py:wandb_internal():88] W&B internal server running at pid: 3052, started at: 2022-11-23 16:01:54.596454
2022-11-23 16:01:54,603 DEBUG   HandlerThread:3052 [handler.py:handle_request():138] handle_request: status
2022-11-23 16:01:54,611 DEBUG   SenderThread:3052 [sender.py:send_request():317] send_request: status
2022-11-23 16:01:54,617 DEBUG   SenderThread:3052 [sender.py:send():303] send: header
2022-11-23 16:01:54,617 INFO    WriterThread:3052 [datastore.py:open_for_write():75] open: C:\Users\adams\OneDrive\Documents\GitHub\Mavi\wandb\run-20221123_160154-3gx49d5s\run-3gx49d5s.wandb
2022-11-23 16:01:54,705 DEBUG   SenderThread:3052 [sender.py:send():303] send: run
2022-11-23 16:01:58,398 ERROR   SenderThread:3052 [retry.py:__call__():154] Retry attempt failed:
Traceback (most recent call last):
  File "C:\Users\adams\AppData\Local\Programs\Python\Python39\lib\site-packages\urllib3\connection.py", line 174, in _new_conn
    conn = connection.create_connection(
  File "C:\Users\adams\AppData\Local\Programs\Python\Python39\lib\site-packages\urllib3\util\connection.py", line 72, in create_connection
    for res in socket.getaddrinfo(host, port, family, socket.SOCK_STREAM):
  File "C:\Users\adams\AppData\Local\Programs\Python\Python39\lib\socket.py", line 953, in getaddrinfo
    for res in _socket.getaddrinfo(host, port, family, type, proto, flags):
socket.gaierror: [Errno 11002] getaddrinfo failed

During handling of the above exception, another exception occurred:

Traceback (most recent call last):
  File "C:\Users\adams\AppData\Local\Programs\Python\Python39\lib\site-packages\urllib3\connectionpool.py", line 703, in urlopen
    httplib_response = self._make_request(
  File "C:\Users\adams\AppData\Local\Programs\Python\Python39\lib\site-packages\urllib3\connectionpool.py", line 386, in _make_request
    self._validate_conn(conn)
  File "C:\Users\adams\AppData\Local\Programs\Python\Python39\lib\site-packages\urllib3\connectionpool.py", line 1042, in _validate_conn
    conn.connect()
  File "C:\Users\adams\AppData\Local\Programs\Python\Python39\lib\site-packages\urllib3\connection.py", line 358, in connect
    self.sock = conn = self._new_conn()
  File "C:\Users\adams\AppData\Local\Programs\Python\Python39\lib\site-packages\urllib3\connection.py", line 186, in _new_conn
    raise NewConnectionError(
urllib3.exceptions.NewConnectionError: <urllib3.connection.HTTPSConnection object at 0x000001D3598993D0>: Failed to establish a new connection: [Errno 11002] getaddrinfo failed

During handling of the above exception, another exception occurred:

Traceback (most recent call last):
  File "C:\Users\adams\AppData\Local\Programs\Python\Python39\lib\site-packages\requests\adapters.py", line 489, in send
    resp = conn.urlopen(
  File "C:\Users\adams\AppData\Local\Programs\Python\Python39\lib\site-packages\urllib3\connectionpool.py", line 787, in urlopen
    retries = retries.increment(
  File "C:\Users\adams\AppData\Local\Programs\Python\Python39\lib\site-packages\urllib3\util\retry.py", line 592, in increment
    raise MaxRetryError(_pool, url, error or ResponseError(cause))
urllib3.exceptions.MaxRetryError: HTTPSConnectionPool(host='api.wandb.ai', port=443): Max retries exceeded with url: /graphql (Caused by NewConnectionError('<urllib3.connection.HTTPSConnection object at 0x000001D3598993D0>: Failed to establish a new connection: [Errno 11002] getaddrinfo failed'))

During handling of the above exception, another exception occurred:

Traceback (most recent call last):
  File "C:\Users\adams\AppData\Local\Programs\Python\Python39\lib\site-packages\wandb\sdk\lib\retry.py", line 113, in __call__
    result = self._call_fn(*args, **kwargs)
  File "C:\Users\adams\AppData\Local\Programs\Python\Python39\lib\site-packages\wandb\sdk\internal\internal_api.py", line 213, in execute
    return self.client.execute(*args, **kwargs)  # type: ignore
  File "C:\Users\adams\AppData\Local\Programs\Python\Python39\lib\site-packages\wandb\vendor\gql-0.2.0\wandb_gql\client.py", line 52, in execute
    result = self._get_result(document, *args, **kwargs)
  File "C:\Users\adams\AppData\Local\Programs\Python\Python39\lib\site-packages\wandb\vendor\gql-0.2.0\wandb_gql\client.py", line 60, in _get_result
    return self.transport.execute(document, *args, **kwargs)
  File "C:\Users\adams\AppData\Local\Programs\Python\Python39\lib\site-packages\wandb\vendor\gql-0.2.0\wandb_gql\transport\requests.py", line 38, in execute
    request = requests.post(self.url, **post_args)
  File "C:\Users\adams\AppData\Local\Programs\Python\Python39\lib\site-packages\requests\api.py", line 115, in post
    return request("post", url, data=data, json=json, **kwargs)
  File "C:\Users\adams\AppData\Local\Programs\Python\Python39\lib\site-packages\requests\api.py", line 59, in request
    return session.request(method=method, url=url, **kwargs)
  File "C:\Users\adams\AppData\Local\Programs\Python\Python39\lib\site-packages\requests\sessions.py", line 587, in request
    resp = self.send(prep, **send_kwargs)
  File "C:\Users\adams\AppData\Local\Programs\Python\Python39\lib\site-packages\requests\sessions.py", line 701, in send
    r = adapter.send(request, **kwargs)
  File "C:\Users\adams\AppData\Local\Programs\Python\Python39\lib\site-packages\requests\adapters.py", line 565, in send
    raise ConnectionError(e, request=request)
requests.exceptions.ConnectionError: HTTPSConnectionPool(host='api.wandb.ai', port=443): Max retries exceeded with url: /graphql (Caused by NewConnectionError('<urllib3.connection.HTTPSConnection object at 0x000001D3598993D0>: Failed to establish a new connection: [Errno 11002] getaddrinfo failed'))
2022-11-23 16:01:59,728 DEBUG   HandlerThread:3052 [handler.py:handle_request():138] handle_request: keepalive
2022-11-23 16:02:04,763 DEBUG   HandlerThread:3052 [handler.py:handle_request():138] handle_request: keepalive
2022-11-23 16:02:09,811 DEBUG   HandlerThread:3052 [handler.py:handle_request():138] handle_request: keepalive
2022-11-23 16:02:14,861 DEBUG   HandlerThread:3052 [handler.py:handle_request():138] handle_request: keepalive
2022-11-23 16:02:19,884 DEBUG   HandlerThread:3052 [handler.py:handle_request():138] handle_request: keepalive
2022-11-23 16:02:24,907 DEBUG   HandlerThread:3052 [handler.py:handle_request():138] handle_request: keepalive
2022-11-23 16:02:29,930 DEBUG   HandlerThread:3052 [handler.py:handle_request():138] handle_request: keepalive
