2022-11-17 14:29:12,962 INFO    StreamThr :9484 [internal.py:wandb_internal():88] W&B internal server running at pid: 9484, started at: 2022-11-17 14:29:12.961976
2022-11-17 14:29:12,964 DEBUG   HandlerThread:9484 [handler.py:handle_request():138] handle_request: status
2022-11-17 14:29:12,967 DEBUG   SenderThread:9484 [sender.py:send_request():317] send_request: status
2022-11-17 14:29:12,969 INFO    WriterThread:9484 [datastore.py:open_for_write():75] open: C:\Users\adams\OneDrive\Documents\GitHub\Mavi\wandb\run-20221117_142912-1lwg9zfv\run-1lwg9zfv.wandb
2022-11-17 14:29:12,969 DEBUG   SenderThread:9484 [sender.py:send():303] send: header
2022-11-17 14:29:13,256 DEBUG   SenderThread:9484 [sender.py:send():303] send: run
2022-11-17 14:29:16,357 ERROR   SenderThread:9484 [retry.py:__call__():154] Retry attempt failed:
Traceback (most recent call last):
  File "C:\Users\adams\AppData\Local\Programs\Python\Python39\lib\site-packages\urllib3\connection.py", line 174, in _new_conn
    conn = connection.create_connection(
  File "C:\Users\adams\AppData\Local\Programs\Python\Python39\lib\site-packages\urllib3\util\connection.py", line 72, in create_connection
    for res in socket.getaddrinfo(host, port, family, socket.SOCK_STREAM):
  File "C:\Users\adams\AppData\Local\Programs\Python\Python39\lib\socket.py", line 953, in getaddrinfo
    for res in _socket.getaddrinfo(host, port, family, type, proto, flags):
socket.gaierror: [Errno 11001] getaddrinfo failed

During handling of the above exception, another exception occurred:

Traceback (most recent call last):
  File "C:\Users\adams\AppData\Local\Programs\Python\Python39\lib\site-packages\urllib3\connectionpool.py", line 703, in urlopen
    httplib_response = self._make_request(
  File "C:\Users\adams\AppData\Local\Programs\Python\Python39\lib\site-packages\urllib3\connectionpool.py", line 386, in _make_request
    self._validate_conn(conn)
  File "C:\Users\adams\AppData\Local\Programs\Python\Python39\lib\site-packages\urllib3\connectionpool.py", line 1042, in _validate_conn
    conn.connect()
  File "C:\Users\adams\AppData\Local\Programs\Python\Python39\lib\site-packages\urllib3\connection.py", line 358, in connect
    self.sock = conn = self._new_conn()
  File "C:\Users\adams\AppData\Local\Programs\Python\Python39\lib\site-packages\urllib3\connection.py", line 186, in _new_conn
    raise NewConnectionError(
urllib3.exceptions.NewConnectionError: <urllib3.connection.HTTPSConnection object at 0x00000237FE268BB0>: Failed to establish a new connection: [Errno 11001] getaddrinfo failed

During handling of the above exception, another exception occurred:

Traceback (most recent call last):
  File "C:\Users\adams\AppData\Local\Programs\Python\Python39\lib\site-packages\requests\adapters.py", line 489, in send
    resp = conn.urlopen(
  File "C:\Users\adams\AppData\Local\Programs\Python\Python39\lib\site-packages\urllib3\connectionpool.py", line 787, in urlopen
    retries = retries.increment(
  File "C:\Users\adams\AppData\Local\Programs\Python\Python39\lib\site-packages\urllib3\util\retry.py", line 592, in increment
    raise MaxRetryError(_pool, url, error or ResponseError(cause))
urllib3.exceptions.MaxRetryError: HTTPSConnectionPool(host='api.wandb.ai', port=443): Max retries exceeded with url: /graphql (Caused by NewConnectionError('<urllib3.connection.HTTPSConnection object at 0x00000237FE268BB0>: Failed to establish a new connection: [Errno 11001] getaddrinfo failed'))

During handling of the above exception, another exception occurred:

Traceback (most recent call last):
  File "C:\Users\adams\AppData\Local\Programs\Python\Python39\lib\site-packages\wandb\sdk\lib\retry.py", line 113, in __call__
    result = self._call_fn(*args, **kwargs)
  File "C:\Users\adams\AppData\Local\Programs\Python\Python39\lib\site-packages\wandb\sdk\internal\internal_api.py", line 213, in execute
    return self.client.execute(*args, **kwargs)  # type: ignore
  File "C:\Users\adams\AppData\Local\Programs\Python\Python39\lib\site-packages\wandb\vendor\gql-0.2.0\wandb_gql\client.py", line 52, in execute
    result = self._get_result(document, *args, **kwargs)
  File "C:\Users\adams\AppData\Local\Programs\Python\Python39\lib\site-packages\wandb\vendor\gql-0.2.0\wandb_gql\client.py", line 60, in _get_result
    return self.transport.execute(document, *args, **kwargs)
  File "C:\Users\adams\AppData\Local\Programs\Python\Python39\lib\site-packages\wandb\vendor\gql-0.2.0\wandb_gql\transport\requests.py", line 38, in execute
    request = requests.post(self.url, **post_args)
  File "C:\Users\adams\AppData\Local\Programs\Python\Python39\lib\site-packages\requests\api.py", line 115, in post
    return request("post", url, data=data, json=json, **kwargs)
  File "C:\Users\adams\AppData\Local\Programs\Python\Python39\lib\site-packages\requests\api.py", line 59, in request
    return session.request(method=method, url=url, **kwargs)
  File "C:\Users\adams\AppData\Local\Programs\Python\Python39\lib\site-packages\requests\sessions.py", line 587, in request
    resp = self.send(prep, **send_kwargs)
  File "C:\Users\adams\AppData\Local\Programs\Python\Python39\lib\site-packages\requests\sessions.py", line 701, in send
    r = adapter.send(request, **kwargs)
  File "C:\Users\adams\AppData\Local\Programs\Python\Python39\lib\site-packages\requests\adapters.py", line 565, in send
    raise ConnectionError(e, request=request)
requests.exceptions.ConnectionError: HTTPSConnectionPool(host='api.wandb.ai', port=443): Max retries exceeded with url: /graphql (Caused by NewConnectionError('<urllib3.connection.HTTPSConnection object at 0x00000237FE268BB0>: Failed to establish a new connection: [Errno 11001] getaddrinfo failed'))
2022-11-17 14:29:18,310 DEBUG   HandlerThread:9484 [handler.py:handle_request():138] handle_request: keepalive
2022-11-17 14:29:23,362 DEBUG   HandlerThread:9484 [handler.py:handle_request():138] handle_request: keepalive
2022-11-17 14:29:28,405 DEBUG   HandlerThread:9484 [handler.py:handle_request():138] handle_request: keepalive
2022-11-17 14:29:33,460 DEBUG   HandlerThread:9484 [handler.py:handle_request():138] handle_request: keepalive
2022-11-17 14:29:38,495 DEBUG   HandlerThread:9484 [handler.py:handle_request():138] handle_request: keepalive
2022-11-17 14:29:43,521 DEBUG   HandlerThread:9484 [handler.py:handle_request():138] handle_request: keepalive
2022-11-17 14:29:48,573 DEBUG   HandlerThread:9484 [handler.py:handle_request():138] handle_request: keepalive
2022-11-17 14:29:53,615 DEBUG   HandlerThread:9484 [handler.py:handle_request():138] handle_request: keepalive
2022-11-17 14:29:58,675 DEBUG   HandlerThread:9484 [handler.py:handle_request():138] handle_request: keepalive
2022-11-17 14:30:03,734 DEBUG   HandlerThread:9484 [handler.py:handle_request():138] handle_request: keepalive
2022-11-17 14:30:08,782 DEBUG   HandlerThread:9484 [handler.py:handle_request():138] handle_request: keepalive
2022-11-17 14:30:14,873 DEBUG   HandlerThread:9484 [handler.py:handle_request():138] handle_request: poll_exit
2022-11-17 14:30:19,917 DEBUG   HandlerThread:9484 [handler.py:handle_request():138] handle_request: keepalive
2022-11-17 14:30:24,980 DEBUG   HandlerThread:9484 [handler.py:handle_request():138] handle_request: keepalive
2022-11-17 14:30:30,027 DEBUG   HandlerThread:9484 [handler.py:handle_request():138] handle_request: keepalive
2022-11-17 14:30:35,064 DEBUG   HandlerThread:9484 [handler.py:handle_request():138] handle_request: keepalive
2022-11-17 14:30:40,123 DEBUG   HandlerThread:9484 [handler.py:handle_request():138] handle_request: keepalive
2022-11-17 14:30:45,150 DEBUG   HandlerThread:9484 [handler.py:handle_request():138] handle_request: keepalive
2022-11-17 14:30:50,181 DEBUG   HandlerThread:9484 [handler.py:handle_request():138] handle_request: keepalive
2022-11-17 14:30:55,239 DEBUG   HandlerThread:9484 [handler.py:handle_request():138] handle_request: keepalive
2022-11-17 14:31:00,290 DEBUG   HandlerThread:9484 [handler.py:handle_request():138] handle_request: keepalive
2022-11-17 14:31:05,337 DEBUG   HandlerThread:9484 [handler.py:handle_request():138] handle_request: keepalive
2022-11-17 14:31:10,360 DEBUG   HandlerThread:9484 [handler.py:handle_request():138] handle_request: keepalive
2022-11-17 14:31:15,416 DEBUG   HandlerThread:9484 [handler.py:handle_request():138] handle_request: keepalive
2022-11-17 14:31:20,460 DEBUG   HandlerThread:9484 [handler.py:handle_request():138] handle_request: keepalive
2022-11-17 14:31:25,497 DEBUG   HandlerThread:9484 [handler.py:handle_request():138] handle_request: keepalive
2022-11-17 14:31:30,532 DEBUG   HandlerThread:9484 [handler.py:handle_request():138] handle_request: keepalive
2022-11-17 14:31:35,580 DEBUG   HandlerThread:9484 [handler.py:handle_request():138] handle_request: keepalive
2022-11-17 14:31:40,614 DEBUG   HandlerThread:9484 [handler.py:handle_request():138] handle_request: keepalive
