
Main training step 0
2022-10-27 12:55:59,591	INFO trainable.py:160 -- Trainable.setup took 24.499 seconds. If your trainable is slow to initialize, consider setting reuse_actors=True to reduce actor creation overheads.
2022-10-27 12:55:59,601	WARNING util.py:65 -- Install gputil for GPU system monitoring.
Backend QtAgg is interactive backend. Turning interactive mode on.
Traceback (most recent call last):
  File "C:\Users\adams\AppData\Local\Programs\Python\Python39\lib\runpy.py", line 197, in _run_module_as_main
    return _run_code(code, main_globals, None,
  File "C:\Users\adams\AppData\Local\Programs\Python\Python39\lib\runpy.py", line 87, in _run_code
    exec(code, run_globals)
  File "c:\Users\adams\.vscode\extensions\ms-python.python-2022.16.1\pythonFiles\lib\python\debugpy\__main__.py", line 39, in <module>
    cli.main()
  File "c:\Users\adams\.vscode\extensions\ms-python.python-2022.16.1\pythonFiles\lib\python\debugpy/..\debugpy\server\cli.py", line 430, in main
    run()
  File "c:\Users\adams\.vscode\extensions\ms-python.python-2022.16.1\pythonFiles\lib\python\debugpy/..\debugpy\server\cli.py", line 284, in run_file
    runpy.run_path(target, run_name="__main__")
  File "c:\Users\adams\.vscode\extensions\ms-python.python-2022.16.1\pythonFiles\lib\python\debugpy\_vendored\pydevd\_pydevd_bundle\pydevd_runpy.py", line 321, in run_path
    return _run_module_code(code, init_globals, run_name,
  File "c:\Users\adams\.vscode\extensions\ms-python.python-2022.16.1\pythonFiles\lib\python\debugpy\_vendored\pydevd\_pydevd_bundle\pydevd_runpy.py", line 135, in _run_module_code
    _run_code(code, mod_globals, init_globals,
  File "c:\Users\adams\.vscode\extensions\ms-python.python-2022.16.1\pythonFiles\lib\python\debugpy\_vendored\pydevd\_pydevd_bundle\pydevd_runpy.py", line 124, in _run_code
    exec(code, run_globals)
  File "c:\Users\adams\OneDrive\Desktop\Masters\MasterThesis\mavi-main\src\raya3c\example_vin.py", line 290, in <module>
    res.append(wfun(a)) # i think this call the function that crashes
  File "c:\Users\adams\OneDrive\Desktop\Masters\MasterThesis\mavi-main\src\raya3c\example_vin.py", line 197, in my_experiment
    result = trainer.train()
  File "C:\Users\adams\AppData\Local\Programs\Python\Python39\lib\site-packages\ray\tune\trainable\trainable.py", line 397, in train
    self.log_result(result)
  File "c:\Users\adams\OneDrive\Desktop\Masters\MasterThesis\mavi-main\src\raya3c\a3c.py", line 188, in log_result
    return super().log_result(result)
  File "C:\Users\adams\AppData\Local\Programs\Python\Python39\lib\site-packages\ray\rllib\algorithms\algorithm.py", line 1561, in log_result
    self.callbacks.on_train_result(algorithm=self, result=result, trainer=self)
  File "C:\Users\adams\OneDrive\Desktop\Masters\MasterThesis\mavi-main\src\raya3c\my_callback.py", line 149, in on_train_result
    #images = self.wandb.Image(image_array, caption="Top: Output, Bottom: Input")
  File "C:\Users\adams\AppData\Local\Programs\Python\Python39\lib\site-packages\wandb\sdk\data_types\image.py", line 153, in __init__
    self._initialize_from_data(data_or_path, mode)
  File "C:\Users\adams\AppData\Local\Programs\Python\Python39\lib\site-packages\wandb\sdk\data_types\image.py", line 279, in _initialize_from_data
    if data.ndim > 2:
AttributeError: 'list' object has no attribute 'ndim'
Traceback (most recent call last):
  File "C:\Users\adams\AppData\Local\Programs\Python\Python39\lib\runpy.py", line 197, in _run_module_as_main
    return _run_code(code, main_globals, None,
  File "C:\Users\adams\AppData\Local\Programs\Python\Python39\lib\runpy.py", line 87, in _run_code
    exec(code, run_globals)
  File "c:\Users\adams\.vscode\extensions\ms-python.python-2022.16.1\pythonFiles\lib\python\debugpy\__main__.py", line 39, in <module>
    cli.main()
  File "c:\Users\adams\.vscode\extensions\ms-python.python-2022.16.1\pythonFiles\lib\python\debugpy/..\debugpy\server\cli.py", line 430, in main
    run()
  File "c:\Users\adams\.vscode\extensions\ms-python.python-2022.16.1\pythonFiles\lib\python\debugpy/..\debugpy\server\cli.py", line 284, in run_file
    runpy.run_path(target, run_name="__main__")
  File "c:\Users\adams\.vscode\extensions\ms-python.python-2022.16.1\pythonFiles\lib\python\debugpy\_vendored\pydevd\_pydevd_bundle\pydevd_runpy.py", line 321, in run_path
    return _run_module_code(code, init_globals, run_name,
  File "c:\Users\adams\.vscode\extensions\ms-python.python-2022.16.1\pythonFiles\lib\python\debugpy\_vendored\pydevd\_pydevd_bundle\pydevd_runpy.py", line 135, in _run_module_code
    _run_code(code, mod_globals, init_globals,
  File "c:\Users\adams\.vscode\extensions\ms-python.python-2022.16.1\pythonFiles\lib\python\debugpy\_vendored\pydevd\_pydevd_bundle\pydevd_runpy.py", line 124, in _run_code
    exec(code, run_globals)
  File "c:\Users\adams\OneDrive\Desktop\Masters\MasterThesis\mavi-main\src\raya3c\example_vin.py", line 290, in <module>
    res.append(wfun(a)) # i think this call the function that crashes
  File "c:\Users\adams\OneDrive\Desktop\Masters\MasterThesis\mavi-main\src\raya3c\example_vin.py", line 197, in my_experiment
    result = trainer.train()
  File "C:\Users\adams\AppData\Local\Programs\Python\Python39\lib\site-packages\ray\tune\trainable\trainable.py", line 397, in train
    self.log_result(result)
  File "c:\Users\adams\OneDrive\Desktop\Masters\MasterThesis\mavi-main\src\raya3c\a3c.py", line 188, in log_result
    return super().log_result(result)
  File "C:\Users\adams\AppData\Local\Programs\Python\Python39\lib\site-packages\ray\rllib\algorithms\algorithm.py", line 1561, in log_result
    self.callbacks.on_train_result(algorithm=self, result=result, trainer=self)
  File "C:\Users\adams\OneDrive\Desktop\Masters\MasterThesis\mavi-main\src\raya3c\my_callback.py", line 149, in on_train_result
    #images = self.wandb.Image(image_array, caption="Top: Output, Bottom: Input")
  File "C:\Users\adams\AppData\Local\Programs\Python\Python39\lib\site-packages\wandb\sdk\data_types\image.py", line 153, in __init__
    self._initialize_from_data(data_or_path, mode)
  File "C:\Users\adams\AppData\Local\Programs\Python\Python39\lib\site-packages\wandb\sdk\data_types\image.py", line 279, in _initialize_from_data
    if data.ndim > 2:
AttributeError: 'list' object has no attribute 'ndim'